<?xml version="1.0"?>
<robot name="my_robot" xmlns:xacro="http://www.ros.org/wiki/xacro">

  <!-- ================= PROPERTIES ================= -->
  <xacro:property name="x_l" value="0.052"/>
  <xacro:property name="y_l" value="0.029"/>
  <xacro:property name="z_l" value="0.008"/>

  <xacro:property name="x_r" value="-0.052"/>
  <xacro:property name="y_r" value="0.029"/>
  <xacro:property name="z_r" value="0.008"/>

  <xacro:property name="x_c" value="0.00"/>
  <xacro:property name="y_c" value="-0.038"/>
  <xacro:property name="z_c" value="0.00"/>

  <!-- ================= BASE ================= -->
  <link name="base_link">

    <inertial>
      <mass value="2.0"/>
      <origin xyz="0 0 0" rpy="0 0 0"/>
      <inertia ixx="0.01" iyy="0.015" izz="0.02"
               ixy="0" ixz="0" iyz="0"/>
    </inertial>

    <visual>
      <origin xyz="0 0 0" rpy="0 0 0"/>
      <geometry>
        <mesh filename="package://my_robot/description/meshes/body.dae" scale="1.0 1.0 1.0"/>
      </geometry>
    </visual>

    <collision>
      <origin xyz="0 0 0.026" rpy="0 0 0"/>
      <geometry>
        <box size="0.086 0.099 0.05379345"/>
      </geometry>
    </collision>

  </link>

  <!-- ================= LEFT WHEEL ================= -->
  <link name="left_wheel">

    <inertial>
      <mass value="0.2"/>
      <origin xyz="0 0 0" rpy="0 0 0"/>
      <inertia ixx="0.0001" iyy="0.0001" izz="0.0001"
               ixy="0" ixz="0" iyz="0"/>
    </inertial>

    <visual>
      <origin xyz="0 0 0" rpy="0 0 0"/>
      <geometry>
        <mesh filename="package://my_robot/description/meshes/roda2.dae" scale="1.0 1.0 1.0"/>
      </geometry>
    </visual>

    <collision>
      <origin xyz="0 0 0" rpy="0 1.5708 0"/>
      <geometry>
        <cylinder radius="0.02131869" length="0.017"/>
      </geometry>
    </collision>

  </link>

  <joint name="left_wheel_joint" type="continuous">
    <parent link="base_link"/>
    <child link="left_wheel"/>
    <origin xyz="${x_l} ${y_l} ${z_l}" rpy="0 0 0"/>
    <axis xyz="1 0 0"/>
  </joint>

  <!-- ================= RIGHT WHEEL ================= -->
  <link name="right_wheel">

    <inertial>
      <mass value="0.2"/>
      <origin xyz="0 0 0" rpy="0 0 0"/>
      <inertia ixx="0.0001" iyy="0.0001" izz="0.0001"
               ixy="0" ixz="0" iyz="0"/>
    </inertial>

    <visual>
      <origin xyz="0 0 0" rpy="0 0 0"/>
      <geometry>
        <mesh filename="package://my_robot/description/meshes/roda1.dae" scale="1.0 1.0 1.0"/>
      </geometry>
    </visual>

    <collision>
      <origin xyz="0 0 0" rpy="0 1.5708 0"/>
      <geometry>
        <cylinder radius="0.02131869" length="0.017"/>
      </geometry>
    </collision>

  </link>

  <joint name="right_wheel_joint" type="continuous">
    <parent link="base_link"/>
    <child link="right_wheel"/>
    <origin xyz="${x_r} ${y_r} ${z_r}" rpy="0 0 0"/>
    <axis xyz="1 0 0"/>
  </joint>

  <!-- ================= CASTER ================= -->
  <link name="caster_wheel">

    <inertial>
      <mass value="0.1"/>
      <origin xyz="0 0 0" rpy="0 0 0"/>
      <inertia ixx="0.00001" iyy="0.00001" izz="0.00001"
               ixy="0" ixz="0" iyz="0"/>
    </inertial>

    <visual>
      <origin xyz="0 0 0" rpy="0 0 0"/>
      <geometry>
        <mesh filename="package://my_robot/description/meshes/freewheel.dae" scale="1.0 1.0 1.0"/>
      </geometry>
    </visual>

  	<collision name="caster_cylinder">
    	<origin xyz="0 0 -0.002" rpy="0 0 0"/>
    	<geometry>
    	  <cylinder radius="0.007850" length="0.012"/>
    	</geometry>
  	</collision>

  	<collision name="caster_sphere">
    	<origin xyz="0 0 -0.009" rpy="0 0 0"/>
    	<geometry>
      	  <sphere radius="0.006"/>
    	</geometry>
  	</collision>

  </link>

  <joint name="caster_joint" type="fixed">
    <parent link="base_link"/>
    <child link="caster_wheel"/>
    <origin xyz="${x_c} ${y_c} ${z_c}" rpy="0 0 0"/>
  </joint>

  <gazebo>
    <plugin filename="gz-sim-diff-drive-system" name="gz::sim::systems::DiffDrive">
      <left_joint>left_wheel_joint</left_joint>
      <right_joint>right_wheel_joint</right_joint>
      <wheel_separation>0.104</wheel_separation>
      <wheel_radius>0.02131869</wheel_radius>
      <topic>/cmd_vel</topic>
      <odom_topic>/odom</odom_topic>
      <tf_topic>/tf</tf_topic>
      <frame_id>odom</frame_id>
      <child_frame_id>base_link</child_frame_id>
    </plugin>
  </gazebo>
</robot>
